Workbook

Sheet How to use
A1: How to use the tracker
A3: 1. Tracker sheet: one row per student per subject. Type in the cream cells only (name, group, teacher, ALIS, TG, support, year group, subject, level, marks).
A4: 2. Year group, Subject, Level and Support are drop-downs. Marks are checked against the maximum mark for that test.
A5: 3. Choose the year group, subject and level in the boxes at the top - the test names, max marks and the status counts update. Level "SL/HL" shows both classes: headings then show the HL test name on the first line and the SL test name on the second, with both max marks.
A6: 4. Use the filter arrows on the header row (Year group, Subject, Level, Teacher, Group) to show just that class. Rows that do not match the boxes at the top are greyed out.
A7: 5. Everything else calculates: %, grade (from the Boundaries sheet), vs ALIS, weighted average %, overall grade, progress from 1st and previous test, and progress status.
A9: Progress status rules
A10: On/above target - overall grade minus ALIS is 0 or more
A11: Improving towards target - below ALIS, but latest grade is at least 0.5 above the first
A12: Declining - below ALIS and latest grade is at least 0.5 below the previous one
A13: Stable below target - below ALIS otherwise
A15: Assessments sheet: one row per test (year group, subject, level, slot 1-14, name, when, max mark, boundary set, weight). Edit names/max marks here; add a row to add a test. Mid course papers have weight 2.
... A21: Hidden columns to the right of the marks do the working - please do not delete them.

Sheet Tracker
A1: Humanities Tracking
A2: Pick a year group, subject and level, then filter the table to match (arrows on the header row). Type in the cream cells only; everything else calculates.
A3: YEAR GROUP | C3: SUBJECT | G3: LEVEL
A4: Grad 2027 | C4: IB Geography | G4: HL
A5: ="All ("&COUNTIFS($H$11:$H$610,$A$4,$I$11:$I$610,$C$4,$J$11:$J$610,IF($G$4="SL/HL","*",$G$4),$A$11:$A$610,"<>")&")" -> All (33) | C5: ="On/above target ("&COUNTIFS($H$11:$H$610,$A$4,$I$11:$I$610,$C$4,$J$11:$J$610,IF($G$4="SL/HL","*",$G$4),$P$11:$P$610,"On/above target")&")" -> On/above target (17) | G5: ="Improving towards target ("&COUNTIFS($H$11:$H$610,$A$4,$I$11:$I$610,$C$4,$J$11:$J$610,IF($G$4="SL/HL","*",$G$4),$P$11:$P$610,"Improving towards target")&")" -> Improving towards target (3) | J5: ="Stable below target ("&COUNTIFS($H$11:$H$610,$A$4,$I$11:$I$610,$C$4,$J$11:$J$610,IF($G$4="SL/HL","*",$G$4),$P$11:$P$610,"Stable below target")&")" -> Stable below target (11) | N5: ="Declining ("&COUNTIFS($H$11:$H$610,$A$4,$I$11:$I$610,$C$4,$J$11:$J$610,IF($G$4="SL/HL","*",$G$4),$P$11:$P$610,"Declining")&")" -> Declining (2)
A6: vs ALIS: | B6: on or above | C6: just below | E6: 1 grade below | H6: 2+ grades below
A8: Student | K8: Overall tracking | Q8: =IF($G$4="SL/HL","HL: "&IFERROR(INDEX(Assessments!$F$2:$F$600,MATCH($A$4&"|"&$C$4&"|HL|"&1,Assessments!$A$2:$A$600,0)),"—"),IFERROR(INDEX(Assessments!$F$2:$F$600,MATCH($A$4&"|"&$C$4&"|"&$G$4&"|"&1,Assessments!$A$2:$A$600,0)),"—")) -> Population | U8: =IF($G$4="SL/HL","HL: "&IFERROR(INDEX(Assessments!$F$2:$F$600,MATCH($A$4&"|"&$C$4&"|HL|"&2,Assessments!$A$2:$A$600,0)),"—"),IFERROR(INDEX(Assessments!$F$2:$F$600,MATCH($A$4&"|"&$C$4&"|"&$G$4&"|"&2,Assessments!$A$2:$A$600,0)),"—")) -> Food & health | Y8: =IF($G$4="SL/HL","HL: "&IFERROR(INDEX(Assessments!$F$2:$F$600,MATCH($A$4&"|"&$C$4&"|HL|"&3,Assessments!$A$2:$A$600,0)),"—"),IFERROR(INDEX(Assessments!$F$2:$F$600,MATCH($A$4&"|"&$C$4&"|"&$G$4&"|"&3,Assessments!$A$2:$A$600,0)),"—")) -> Population (P2) | AC8: =IF($G$4="SL/HL","HL: "&IFERROR(INDEX(Assessments!$F$2:$F$600,MATCH($A$4&"|"&$C$4&"|HL|"&4,Assessments!$A$2:$A$600,0)),"—"),IFERROR(INDEX(Assessments!$F$2:$F$600,MATCH($A$4&"|"&$C$4&"|"&$G$4&"|"&4,Assessments!$A$2:$A$600,0)),"—")) -> Freshwater | AG8: =IF($G$4="SL/HL","HL: "&IFERROR(INDEX(Assessments!$F$2:$F$600,MATCH($A$4&"|"&$C$4&"|HL|"&5,Assessments!$A$2:$A$600,0)),"—"),IFERROR(INDEX(Assessments!$F$2:$F$600,MATCH($A$4&"|"&$C$4&"|"&$G$4&"|"&5,Assessments!$A$2:$A$600,0)),"—")) -> Food & health | AK8: =IF($G$4="SL/HL","HL: "&IFERROR(INDEX(Assessments!$F$2:$F$600,MATCH($A$4&"|"&$C$4&"|HL|"&6,Assessments!$A$2:$A$600,0)),"—"),IFERROR(INDEX(Assessments!$F$2:$F$600,MATCH($A$4&"|"&$C$4&"|"&$G$4&"|"&6,Assessments!$A$2:$A$600,0)),"—")) -> Mid course P1 | AO8: =IF($G$4="SL/HL","HL: "&IFERROR(INDEX(Assessments!$F$2:$F$600,MATCH($A$4&"|"&$C$4&"|HL|"&7,Assessments!$A$2:$A$600,0)),"—"),IFERROR(INDEX(Assessments!$F$2:$F$600,MATCH($A$4&"|"&$C$4&"|"&$G$4&"|"&7,Assessments!$A$2:$A$600,0)),"—")) -> Mid course P2 | AS8: =IF($G$4="SL/HL","HL: "&IFERROR(INDEX(Assessments!$F$2:$F$600,MATCH($A$4&"|"&$C$4&"|HL|"&8,Assessments!$A$2:$A$600,0)),"—"),IFERROR(INDEX(Assessments!$F$2:$F$600,MATCH($A$4&"|"&$C$4&"|"&$G$4&"|"&8,Assessments!$A$2:$A$600,0)),"—")) -> IA | AW8: =IF($G$4="SL/HL","HL: "&IFERROR(INDEX(Assessments!$F$2:$F$600,MATCH($A$4&"|"&$C$4&"|HL|"&9,Assessments!$A$2:$A$600,0)),"—"),IFERROR(INDEX(Assessments!$F$2:$F$600,MATCH($A$4&"|"&$C$4&"|"&$G$4&"|"&9,Assessments!$A$2:$A$600,0)),"—")) -> HL essay | BA8: =IF($G$4="SL/HL","HL: "&IFERROR(INDEX(Assessments!$F$2:$F$600,MATCH($A$4&"|"&$C$4&"|HL|"&10,Assessments!$A$2:$A$600,0)),"—"),IFERROR(INDEX(Assessments!$F$2:$F$600,MATCH($A$4&"|"&$C$4&"|"&$G$4&"|"&10,Assessments!$A$2:$A$600,0)),"—")) -> Climate change | BE8: =IF($G$4="SL/HL","HL: "&IFERROR(INDEX(Assessments!$F$2:$F$600,MATCH($A$4&"|"&$C$4&"|HL|"&11,Assessments!$A$2:$A$600,0)),"—"),IFERROR(INDEX(Assessments!$F$2:$F$600,MATCH($A$4&"|"&$C$4&"|"&$G$4&"|"&11,Assessments!$A$2:$A$600,0)),"—")) -> — | BI8: =IF($G$4="SL/HL","HL: "&IFERROR(INDEX(Assessments!$F$2:$F$600,MATCH($A$4&"|"&$C$4&"|HL|"&12,Assessments!$A$2:$A$600,0)),"—"),IFERROR(INDEX(Assessments!$F$2:$F$600,MATCH($A$4&"|"&$C$4&"|"&$G$4&"|"&12,Assessments!$A$2:$A$600,0)),"—")) -> — | BM8: =IF($G$4="SL/HL","HL: "&IFERROR(INDEX(Assessments!$F$2:$F$600,MATCH($A$4&"|"&$C$4&"|HL|"&13,Assessments!$A$2:$A$600,0)),"—"),IFERROR(INDEX(Assessments!$F$2:$F$600,MATCH($A$4&"|"&$C$4&"|"&$G$4&"|"&13,Assessments!$A$2:$A$600,0)),"—")) -> — | BQ8: =IF($G$4="SL/HL","HL: "&IFERROR(INDEX(Assessments!$F$2:$F$600,MATCH($A$4&"|"&$C$4&"|HL|"&14,Assessments!$A$2:$A$600,0)),"—"),IFERROR(INDEX(Assessments!$F$2:$F$600,MATCH($A$4&"|"&$C$4&"|"&$G$4&"|"&14,Assessments!$A$2:$A$600,0)),"—")) -> —
K9: =IFERROR(IF($G$4="SL/HL","HL: "&INDEX(Lists!$G$2:$G$20,MATCH($C$4&"|"&"HL",Lists!$F$2:$F$20,0))&" · SL: "&INDEX(Lists!$G$2:$G$20,MATCH($C$4&"|"&"SL",Lists!$F$2:$F$20,0)),INDEX(Lists!$G$2:$G$20,MATCH($C$4&"|"&$G$4,Lists!$F$2:$F$20,0))&" boundaries"),"") -> Geog Overall HL boundaries | Q9: =IF($G$4="SL/HL","SL: "&IFERROR(INDEX(Assessments!$F$2:$F$600,MATCH($A$4&"|"&$C$4&"|SL|"&1,Assessments!$A$2:$A$600,0)),"—"),IFERROR(INDEX(Assessments!$G$2:$G$600,MATCH($A$4&"|"&$C$4&"|"&$G$4&"|"&1,Assessments!$A$2:$A$600,0))&IF(INDEX(Assessments!$J$2:$J$600,MATCH($A$4&"|"&$C$4&"|"&$G$4&"|"&1,Assessments!$A$2:$A$600,0))>1," · ×"&INDEX(Assessments!$J$2:$J$600,MATCH($A$4&"|"&$C$4&"|"&$G$4&"|"&1,Assessments!$A$2:$A$600,0)),""),"")) -> Y12 T1 Wk 8 | U9: =IF($G$4="SL/HL","SL: "&IFERROR(INDEX(Assessments!$F$2:$F$600,MATCH($A$4&"|"&$C$4&"|SL|"&2,Assessments!$A$2:$A$600,0)),"—"),IFERROR(INDEX(Assessments!$G$2:$G$600,MATCH($A$4&"|"&$C$4&"|"&$G$4&"|"&2,Assessments!$A$2:$A$600,0))&IF(INDEX(Assessments!$J$2:$J$600,MATCH($A$4&"|"&$C$4&"|"&$G$4&"|"&2,Assessments!$A$2:$A$600,0))>1," · ×"&INDEX(Assessments!$J$2:$J$600,MATCH($A$4&"|"&$C$4&"|"&$G$4&"|"&2,Assessments!$A$2:$A$600,0)),""),"")) -> Y12 T1 Wk 13 | Y9: =IF($G$4="SL/HL","SL: "&IFERROR(INDEX(Assessments!$F$2:$F$600,MATCH($A$4&"|"&$C$4&"|SL|"&3,Assessments!$A$2:$A$600,0)),"—"),IFERROR(INDEX(Assessments!$G$2:$G$600,MATCH($A$4&"|"&$C$4&"|"&$G$4&"|"&3,Assessments!$A$2:$A$600,0))&IF(INDEX(Assessments!$J$2:$J$600,MATCH($A$4&"|"&$C$4&"|"&$G$4&"|"&3,Assessments!$A$2:$A$600,0))>1," · ×"&INDEX(Assessments!$J$2:$J$600,MATCH($A$4&"|"&$C$4&"|"&$G$4&"|"&3,Assessments!$A$2:$A$600,0)),""),"")) -> Y12 T1 Wk 13 | AC9: =IF($G$4="SL/HL","SL: "&IFERROR(INDEX(Assessments!$F$2:$F$600,MATCH($A$4&"|"&$C$4&"|SL|"&4,Assessments!$A$2:$A$600,0)),"—"),IFERROR(INDEX(Assessments!$G$2:$G$600,MATCH($A$4&"|"&$C$4&"|"&$G$4&"|"&4,Assessments!$A$2:$A$600,0))&IF(INDEX(Assessments!$J$2:$J$600,MATCH($A$4&"|"&$C$4&"|"&$G$4&"|"&4,Assessments!$A$2:$A$600,0))>1," · ×"&INDEX(Assessments!$J$2:$J$600,MATCH($A$4&"|"&$C$4&"|"&$G$4&"|"&4,Assessments!$A$2:$A$600,0)),""),"")) -> Y12 T2 Wk 6 | AG9: =IF($G$4="SL/HL","SL: "&IFERROR(INDEX(Assessments!$F$2:$F$600,MATCH($A$4&"|"&$C$4&"|SL|"&5,Assessments!$A$2:$A$600,0)),"—"),IFERROR(INDEX(Assessments!$G$2:$G$600,MATCH($A$4&"|"&$C$4&"|"&$G$4&"|"&5,Assessments!$A$2:$A$600,0))&IF(INDEX(Assessments!$J$2:$J$600,MATCH($A$4&"|"&$C$4&"|"&$G$4&"|"&5,Assessments!$A$2:$A$600,0))>1," · ×"&INDEX(Assessments!$J$2:$J$600,MATCH($A$4&"|"&$C$4&"|"&$G$4&"|"&5,Assessments!$A$2:$A$600,0)),""),"")) -> Y12 T2 Wk 9 | AK9: =IF($G$4="SL/HL","SL: "&IFERROR(INDEX(Assessments!$F$2:$F$600,MATCH($A$4&"|"&$C$4&"|SL|"&6,Assessments!$A$2:$A$600,0)),"—"),IFERROR(INDEX(Assessments!$G$2:$G$600,MATCH($A$4&"|"&$C$4&"|"&$G$4&"|"&6,Assessments!$A$2:$A$600,0))&IF(INDEX(Assessments!$J$2:$J$600,MATCH($A$4&"|"&$C$4&"|"&$G$4&"|"&6,Assessments!$A$2:$A$600,0))>1," · ×"&INDEX(Assessments!$J$2:$J$600,MATCH($A$4&"|"&$C$4&"|"&$G$4&"|"&6,Assessments!$A$2:$A$600,0)),""),"")) -> Y12 T3 · ×2 | AO9: =IF($G$4="SL/HL","SL: "&IFERROR(INDEX(Assessments!$F$2:$F$600,MATCH($A$4&"|"&$C$4&"|SL|"&7,Assessments!$A$2:$A$600,0)),"—"),IFERROR(INDEX(Assessments!$G$2:$G$600,MATCH($A$4&"|"&$C$4&"|"&$G$4&"|"&7,Assessments!$A$2:$A$600,0))&IF(INDEX(Assessments!$J$2:$J$600,MATCH($A$4&"|"&$C$4&"|"&$G$4&"|"&7,Assessments!$A$2:$A$600,0))>1," · ×"&INDEX(Assessments!$J$2:$J$600,MATCH($A$4&"|"&$C$4&"|"&$G$4&"|"&7,Assessments!$A$2:$A$600,0)),""),"")) -> Y12 T3 · ×2 | AS9: =IF($G$4="SL/HL","SL: "&IFERROR(INDEX(Assessments!$F$2:$F$600,MATCH($A$4&"|"&$C$4&"|SL|"&8,Assessments!$A$2:$A$600,0)),"—"),IFERROR(INDEX(Assessments!$G$2:$G$600,MATCH($A$4&"|"&$C$4&"|"&$G$4&"|"&8,Assessments!$A$2:$A$600,0))&IF(INDEX(Assessments!$J$2:$J$600,MATCH($A$4&"|"&$C$4&"|"&$G$4&"|"&8,Assessments!$A$2:$A$600,0))>1," · ×"&INDEX(Assessments!$J$2:$J$600,MATCH($A$4&"|"&$C$4&"|"&$G$4&"|"&8,Assessments!$A$2:$A$600,0)),""),"")) -> Y13 T1 Wk 4 | AW9: =IF($G$4="SL/HL","SL: "&IFERROR(INDEX(Assessments!$F$2:$F$600,MATCH($A$4&"|"&$C$4&"|SL|"&9,Assessments!$A$2:$A$600,0)),"—"),IFERROR(INDEX(Assessments!$G$2:$G$600,MATCH($A$4&"|"&$C$4&"|"&$G$4&"|"&9,Assessments!$A$2:$A$600,0))&IF(INDEX(Assessments!$J$2:$J$600,MATCH($A$4&"|"&$C$4&"|"&$G$4&"|"&9,Assessments!$A$2:$A$600,0))>1," · ×"&INDEX(Assessments!$J$2:$J$600,MATCH($A$4&"|"&$C$4&"|"&$G$4&"|"&9,Assessments!$A$2:$A$600,0)),""),"")) -> Y13 T1 Wk 5 | BA9: =IF($G$4="SL/HL","SL: "&IFERROR(INDEX(Assessments!$F$2:$F$600,MATCH($A$4&"|"&$C$4&"|SL|"&10,Assessments!$A$2:$A$600,0)),"—"),IFERROR(INDEX(Assessments!$G$2:$G$600,MATCH($A$4&"|"&$C$4&"|"&$G$4&"|"&10,Assessments!$A$2:$A$600,0))&IF(INDEX(Assessments!$J$2:$J$600,MATCH($A$4&"|"&$C$4&"|"&$G$4&"|"&10,Assessments!$A$2:$A$600,0))>1," · ×"&INDEX(Assessments!$J$2:$J$600,MATCH($A$4&"|"&$C$4&"|"&$G$4&"|"&10,Assessments!$A$2:$A$600,0)),""),"")) -> Y13 T1 Wk 5 | BE9: =IF($G$4="SL/HL","SL: "&IFERROR(INDEX(Assessments!$F$2:$F$600,MATCH($A$4&"|"&$C$4&"|SL|"&11,Assessments!$A$2:$A$600,0)),"—"),IFERROR(INDEX(Assessments!$G$2:$G$600,MATCH($A$4&"|"&$C$4&"|"&$G$4&"|"&11,Assessments!$A$2:$A$600,0))&IF(INDEX(Assessments!$J$2:$J$600,MATCH($A$4&"|"&$C$4&"|"&$G$4&"|"&11,Assessments!$A$2:$A$600,0))>1," · ×"&INDEX(Assessments!$J$2:$J$600,MATCH($A$4&"|"&$C$4&"|"&$G$4&"|"&11,Assessments!$A$2:$A$600,0)),""),"")) | BI9: =IF($G$4="SL/HL","SL: "&IFERROR(INDEX(Assessments!$F$2:$F$600,MATCH($A$4&"|"&$C$4&"|SL|"&12,Assessments!$A$2:$A$600,0)),"—"),IFERROR(INDEX(Assessments!$G$2:$G$600,MATCH($A$4&"|"&$C$4&"|"&$G$4&"|"&12,Assessments!$A$2:$A$600,0))&IF(INDEX(Assessments!$J$2:$J$600,MATCH($A$4&"|"&$C$4&"|"&$G$4&"|"&12,Assessments!$A$2:$A$600,0))>1," · ×"&INDEX(Assessments!$J$2:$J$600,MATCH($A$4&"|"&$C$4&"|"&$G$4&"|"&12,Assessments!$A$2:$A$600,0)),""),"")) | BM9: =IF($G$4="SL/HL","SL: "&IFERROR(INDEX(Assessments!$F$2:$F$600,MATCH($A$4&"|"&$C$4&"|SL|"&13,Assessments!$A$2:$A$600,0)),"—"),IFERROR(INDEX(Assessments!$G$2:$G$600,MATCH($A$4&"|"&$C$4&"|"&$G$4&"|"&13,Assessments!$A$2:$A$600,0))&IF(INDEX(Assessments!$J$2:$J$600,MATCH($A$4&"|"&$C$4&"|"&$G$4&"|"&13,Assessments!$A$2:$A$600,0))>1," · ×"&INDEX(Assessments!$J$2:$J$600,MATCH($A$4&"|"&$C$4&"|"&$G$4&"|"&13,Assessments!$A$2:$A$600,0)),""),"")) | BQ9: =IF($G$4="SL/HL","SL: "&IFERROR(INDEX(Assessments!$F$2:$F$600,MATCH($A$4&"|"&$C$4&"|SL|"&14,Assessments!$A$2:$A$600,0)),"—"),IFERROR(INDEX(Assessments!$G$2:$G$600,MATCH($A$4&"|"&$C$4&"|"&$G$4&"|"&14,Assessments!$A$2:$A$600,0))&IF(INDEX(Assessments!$J$2:$J$600,MATCH($A$4&"|"&$C$4&"|"&$G$4&"|"&14,Assessments!$A$2:$A$600,0))>1," · ×"&INDEX(Assessments!$J$2:$J$600,MATCH($A$4&"|"&$C$4&"|"&$G$4&"|"&14,Assessments!$A$2:$A$600,0)),""),""))
A10: First name | B10: Surname | C10: Group | D10: Teacher | E10: ALIS | F10: TG | G10: Support | H10: Year group | I10: Subject | J10: Level | K10: Avg vs ALIS | L10: Avg % | M10: Grade | N10: From 1st | O10: From prev. | P10: Progress status | Q10: =IF($G$4="SL/HL",IFERROR("/"&INDEX(Assessments!$H$2:$H$600,MATCH($A$4&"|"&$C$4&"|HL|"&1,Assessments!$A$2:$A$600,0)),"–")&" | "&IFERROR("/"&INDEX(Assessments!$H$2:$H$600,MATCH($A$4&"|"&$C$4&"|SL|"&1,Assessments!$A$2:$A$600,0)),"–"),IFERROR("/"&INDEX(Assessments!$H$2:$H$600,MATCH($A$4&"|"&$C$4&"|"&$G$4&"|"&1,Assessments!$A$2:$A$600,0)),"Mark")) -> /20 | R10: % | S10: Grade | T10: vs ALIS | U10: =IF($G$4="SL/HL",IFERROR("/"&INDEX(Assessments!$H$2:$H$600,MATCH($A$4&"|"&$C$4&"|HL|"&2,Assessments!$A$2:$A$600,0)),"–")&" | "&IFERROR("/"&INDEX(Assessments!$H$2:$H$600,MATCH($A$4&"|"&$C$4&"|SL|"&2,Assessments!$A$2:$A$600,0)),"–"),IFERROR("/"&INDEX(Assessments!$H$2:$H$600,MATCH($A$4&"|"&$C$4&"|"&$G$4&"|"&2,Assessments!$A$2:$A$600,0)),"Mark")) -> /20 | V10: % | W10: Grade | X10: vs ALIS | Y10: =IF($G$4="SL/HL",IFERROR("/"&INDEX(Assessments!$H$2:$H$600,MATCH($A$4&"|"&$C$4&"|HL|"&3,Assessments!$A$2:$A$600,0)),"–")&" | "&IFERROR("/"&INDEX(Assessments!$H$2:$H$600,MATCH($A$4&"|"&$C$4&"|SL|"&3,Assessments!$A$2:$A$600,0)),"–"),IFERROR("/"&INDEX(Assessments!$H$2:$H$600,MATCH($A$4&"|"&$C$4&"|"&$G$4&"|"&3,Assessments!$A$2:$A$600,0)),"Mark")) -> /20 | Z10: % | AA10: Grade | AB10: vs ALIS | AC10: =IF($G$4="SL/HL",IFERROR("/"&INDEX(Assessments!$H$2:$H$600,MATCH($A$4&"|"&$C$4&"|HL|"&4,Assessments!$A$2:$A$600,0)),"–")&" | "&IFERROR("/"&INDEX(Assessments!$H$2:$H$600,MATCH($A$4&"|"&$C$4&"|SL|"&4,Assessments!$A$2:$A$600,0)),"–"),IFERROR("/"&INDEX(Assessments!$H$2:$H$600,MATCH($A$4&"|"&$C$4&"|"&$G$4&"|"&4,Assessments!$A$2:$A$600,0)),"Mark")) -> /20 | AD10: % | AE10: Grade | AF10: vs ALIS | AG10: =IF($G$4="SL/HL",IFERROR("/"&INDEX(Assessments!$H$2:$H$600,MATCH($A$4&"|"&$C$4&"|HL|"&5,Assessments!$A$2:$A$600,0)),"–")&" | "&IFERROR("/"&INDEX(Assessments!$H$2:$H$600,MATCH($A$4&"|"&$C$4&"|SL|"&5,Assessments!$A$2:$A$600,0)),"–"),IFERROR("/"&INDEX(Assessments!$H$2:$H$600,MATCH($A$4&"|"&$C$4&"|"&$G$4&"|"&5,Assessments!$A$2:$A$600,0)),"Mark")) -> /20 | AH10: % | AI10: Grade | AJ10: vs ALIS | AK10: =IF($G$4="SL/HL",IFERROR("/"&INDEX(Assessments!$H$2:$H$600,MATCH($A$4&"|"&$C$4&"|HL|"&6,Assessments!$A$2:$A$600,0)),"–")&" | "&IFERROR("/"&INDEX(Assessments!$H$2:$H$600,MATCH($A$4&"|"&$C$4&"|SL|"&6,Assessments!$A$2:$A$600,0)),"–"),IFERROR("/"&INDEX(Assessments!$H$2:$H$600,MATCH($A$4&"|"&$C$4&"|"&$G$4&"|"&6,Assessments!$A$2:$A$600,0)),"Mark")) -> /40 | AL10: % | AM10: Grade | AN10: vs ALIS | AO10: =IF($G$4="SL/HL",IFERROR("/"&INDEX(Assessments!$H$2:$H$600,MATCH($A$4&"|"&$C$4&"|HL|"&7,Assessments!$A$2:$A$600,0)),"–")&" | "&IFERROR("/"&INDEX(Assessments!$H$2:$H$600,MATCH($A$4&"|"&$C$4&"|SL|"&7,Assessments!$A$2:$A$600,0)),"–"),IFERROR("/"&INDEX(Assessments!$H$2:$H$600,MATCH($A$4&"|"&$C$4&"|"&$G$4&"|"&7,Assessments!$A$2:$A$600,0)),"Mark")) -> /50 | AP10: % | AQ10: Grade | AR10: vs ALIS | AS10: =IF($G$4="SL/HL",IFERROR("/"&INDEX(Assessments!$H$2:$H$600,MATCH($A$4&"|"&$C$4&"|HL|"&8,Assessments!$A$2:$A$600,0)),"–")&" | "&IFERROR("/"&INDEX(Assessments!$H$2:$H$600,MATCH($A$4&"|"&$C$4&"|SL|"&8,Assessments!$A$2:$A$600,0)),"–"),IFERROR("/"&INDEX(Assessments!$H$2:$H$600,MATCH($A$4&"|"&$C$4&"|"&$G$4&"|"&8,Assessments!$A$2:$A$600,0)),"Mark")) -> /25 | AT10: % | AU10: Grade | AV10: vs ALIS | AW10: =IF($G$4="SL/HL",IFERROR("/"&INDEX(Assessments!$H$2:$H$600,MATCH($A$4&"|"&$C$4&"|HL|"&9,Assessments!$A$2:$A$600,0)),"–")&" | "&IFERROR("/"&INDEX(Assessments!$H$2:$H$600,MATCH($A$4&"|"&$C$4&"|SL|"&9,Assessments!$A$2:$A$600,0)),"–"),IFERROR("/"&INDEX(Assessments!$H$2:$H$600,MATCH($A$4&"|"&$C$4&"|"&$G$4&"|"&9,Assessments!$A$2:$A$600,0)),"Mark")) -> /16 | AX10: % | AY10: Grade | AZ10: vs ALIS | BA10: =IF($G$4="SL/HL",IFERROR("/"&INDEX(Assessments!$H$2:$H$600,MATCH($A$4&"|"&$C$4&"|HL|"&10,Assessments!$A$2:$A$600,0)),"–")&" | "&IFERROR("/"&INDEX(Assessments!$H$2:$H$600,MATCH($A$4&"|"&$C$4&"|SL|"&10,Assessments!$A$2:$A$600,0)),"–"),IFERROR("/"&INDEX(Assessments!$H$2:$H$600,MATCH($A$4&"|"&$C$4&"|"&$G$4&"|"&10,Assessments!$A$2:$A$600,0)),"Mark")) -> /30 | BB10: % | BC10: Grade | BD10: vs ALIS | BE10: =IF($G$4="SL/HL",IFERROR("/"&INDEX(Assessments!$H$2:$H$600,MATCH($A$4&"|"&$C$4&"|HL|"&11,Assessments!$A$2:$A$600,0)),"–")&" | "&IFERROR("/"&INDEX(Assessments!$H$2:$H$600,MATCH($A$4&"|"&$C$4&"|SL|"&11,Assessments!$A$2:$A$600,0)),"–"),IFERROR("/"&INDEX(Assessments!$H$2:$H$600,MATCH($A$4&"|"&$C$4&"|"&$G$4&"|"&11,Assessments!$A$2:$A$600,0)),"Mark")) -> Mark | BF10: % | BG10: Grade | BH10: vs ALIS | BI10: =IF($G$4="SL/HL",IFERROR("/"&INDEX(Assessments!$H$2:$H$600,MATCH($A$4&"|"&$C$4&"|HL|"&12,Assessments!$A$2:$A$600,0)),"–")&" | "&IFERROR("/"&INDEX(Assessments!$H$2:$H$600,MATCH($A$4&"|"&$C$4&"|SL|"&12,Assessments!$A$2:$A$600,0)),"–"),IFERROR("/"&INDEX(Assessments!$H$2:$H$600,MATCH($A$4&"|"&$C$4&"|"&$G$4&"|"&12,Assessments!$A$2:$A$600,0)),"Mark")) -> Mark | BJ10: % | BK10: Grade | BL10: vs ALIS | BM10: =IF($G$4="SL/HL",IFERROR("/"&INDEX(Assessments!$H$2:$H$600,MATCH($A$4&"|"&$C$4&"|HL|"&13,Assessments!$A$2:$A$600,0)),"–")&" | "&IFERROR("/"&INDEX(Assessments!$H$2:$H$600,MATCH($A$4&"|"&$C$4&"|SL|"&13,Assessments!$A$2:$A$600,0)),"–"),IFERROR("/"&INDEX(Assessments!$H$2:$H$600,MATCH($A$4&"|"&$C$4&"|"&$G$4&"|"&13,Assessments!$A$2:$A$600,0)),"Mark")) -> Mark | BN10: % | BO10: Grade | BP10: vs ALIS | BQ10: =IF($G$4="SL/HL",IFERROR("/"&INDEX(Assessments!$H$2:$H$600,MATCH($A$4&"|"&$C$4&"|HL|"&14,Assessments!$A$2:$A$600,0)),"–")&" | "&IFERROR("/"&INDEX(Assessments!$H$2:$H$600,MATCH($A$4&"|"&$C$4&"|SL|"&14,Assessments!$A$2:$A$600,0)),"–"),IFERROR("/"&INDEX(Assessments!$H$2:$H$600,MATCH($A$4&"|"&$C$4&"|"&$G$4&"|"&14,Assessments!$A$2:$A$600,0)),"Mark")) -> Mark | BR10: % | BS10: Grade | BT10: vs ALIS | BU10: Max1 | BV10: Max2 | BW10: Max3 | BX10: Max4 | BY10: Max5 | BZ10: Max6 | CA10: Max7 | CB10: Max8 | CC10: Max9 | CD10: Max10 | CE10: Max11 | CF10: Max12 | CG10: Max13 | CH10: Max14 | CI10: Set1 | CJ10: Set2 | CK10: Set3 | CL10: Set4 | CM10: Set5 | CN10: Set6 | CO10: Set7 | CP10: Set8 | CQ10: Set9 | CR10: Set10 | CS10: Set11 | CT10: Set12 | CU10: Set13 | CV10: Set14 | CW10: W1 | CX10: W2 | CY10: W3 | CZ10: W4 | DA10: W5 | DB10: W6 | DC10: W7 | DD10: W8 | DE10: W9 | DF10: W10 | DG10: W11 | DH10: W12 | DI10: W13 | DJ10: W14 | DK10: G1 | DL10: G2 | DM10: G3 | DN10: G4 | DO10: G5 | DP10: G6 | DQ10: G7 | DR10: G8 | DS10: G9 | DT10: G10 | DU10: G11 | DV10: G12 | DW10: G13 | DX10: G14 | DY10: Pos1 | DZ10: Pos2 | EA10: Pos3 | EB10: Pos4 | EC10: Pos5 | ED10: Pos6 | EE10: Pos7 | EF10: Pos8 | EG10: Pos9 | EH10: Pos10 | EI10: Pos11 | EJ10: Pos12 | EK10: Pos13 | EL10: Pos14 | EM10: PW1 | EN10: PW2 | EO10: PW3 | EP10: PW4 | EQ10: PW5 | ER10: PW6 | ES10: PW7 | ET10: PW8 | EU10: PW9 | EV10: PW10 | EW10: PW11 | EX10: PW12 | EY10: PW13 | EZ10: PW14 | FA10: WE1 | FB10: WE2 | FC10: WE3 | FD10: WE4 | FE10: WE5 | FF10: WE6 | FG10: WE7 | FH10: WE8 | FI10: WE9 | FJ10: WE10 | FK10: WE11 | FL10: WE12 | FM10: WE13 | FN10: WE14 | FO10: OverallSet
A11: Sira (KK) | B11: Anuras | C11: 12.3 | D11: KEWR | E11: 6.8 | F11: 7 | G11: Y | H11: Grad 2027 | I11: IB Geography | J11: HL | K11: =IF(OR(M11="",$E11=""),"",M11-$E11) -> -0.8 | L11: =IF(SUM(FA11:FN11)=0,"",SUM(EM11:EZ11)/SUM(FA11:FN11)) -> 70.666667 | M11: =IF(OR(L11="",FO11=""),"",IFERROR(MATCH(L11,INDEX(Boundaries!$B$2:$I$30,MATCH(FO11,Boundaries!$A$2:$A$30,0),0),1)-1,"")) -> 6 | N11: =IF(COUNT($DY11:$EL11)<2,"",INDEX($DK11:$DX11,MAX($DY11:$EL11))-INDEX($DK11:$DX11,MIN($DY11:$EL11))) -> 0 | O11: =IF(COUNT($DY11:$EL11)<2,"",INDEX($DK11:$DX11,MAX($DY11:$EL11))-INDEX($DK11:$DX11,LARGE($DY11:$EL11,2))) -> 0 | P11: =IF(K11="","",IF(K11>=0,"On/above target",IF(AND(N11<>"",N11>=0.5),"Improving towards target",IF(AND(O11<>"",O11<=-0.5),"Declining","Stable below target")))) -> Stable below target | Q11: 13 | R11: =IF(OR(Q11="",BU11=""),"",Q11/BU11*100) -> 65 | S11: =IF(R11="","",IFERROR(MATCH(R11,INDEX(Boundaries!$B$2:$I$30,MATCH(CI11,Boundaries!$A$2:$A$30,0),0),1)-1,"")) -> 6 | T11: =IF(OR(S11="",$E11=""),"",S11-$E11) -> -0.8 | U11: 13 | V11: =IF(OR(U11="",BV11=""),"",U11/BV11*100) -> 65 | W11: =IF(V11="","",IFERROR(MATCH(V11,INDEX(Boundaries!$B$2:$I$30,MATCH(CJ11,Boundaries!$A$2:$A$30,0),0),1)-1,"")) -> 6 | X11: =IF(OR(W11="",$E11=""),"",W11-$E11) -> -0.8 | Y11: 13 | Z11: =IF(OR(Y11="",BW11=""),"",Y11/BW11*100) -> 65 | AA11: =IF(Z11="","",IFERROR(MATCH(Z11,INDEX(Boundaries!$B$2:$I$30,MATCH(CK11,Boundaries!$A$2:$A$30,0),0),1)-1,"")) -> 5 | AB11: =IF(OR(AA11="",$E11=""),"",AA11-$E11) -> -1.8 | AC11: 18 | AD11: =IF(OR(AC11="",BX11=""),"",AC11/BX11*100) -> 90 | AE11: =IF(AD11="","",IFERROR(MATCH(AD11,INDEX(Boundaries!$B$2:$I$30,MATCH(CL11,Boundaries!$A$2:$A$30,0),0),1)-1,"")) -> 7 | AF11: =IF(OR(AE11="",$E11=""),"",AE11-$E11) -> 0.2 | AG11: 18 | AH11: =IF(OR(AG11="",BY11=""),"",AG11/BY11*100) -> 90 | AI11: =IF(AH11="","",IFERROR(MATCH(AH11,INDEX(Boundaries!$B$2:$I$30,MATCH(CM11,Boundaries!$A$2:$A$30,0),0),1)-1,"")) -> 7 | AJ11: =IF(OR(AI11="",$E11=""),"",AI11-$E11) -> 0.2 | AK11: 25 | AL11: =IF(OR(AK11="",BZ11=""),"",AK11/BZ11*100) -> 62.5 | AM11: =IF(AL11="","",IFERROR(MATCH(AL11,INDEX(Boundaries!$B$2:$I$30,MATCH(CN11,Boundaries!$A$2:$A$30,0),0),1)-1,"")) -> 6 | AN11: =IF(OR(AM11="",$E11=""),"",AM11-$E11) -> -0.8 | AO11: 34 | AP11: =IF(OR(AO11="",CA11=""),"",AO11/CA11*100) -> 68 | AQ11: =IF(AP11="","",IFERROR(MATCH(AP11,INDEX(Boundaries!$B$2:$I$30,MATCH(CO11,Boundaries!$A$2:$A$30,0),0),1)-1,"")) -> 6 | AR11: =IF(OR(AQ11="",$E11=""),"",AQ11-$E11) -> -0.8 | AT11: =IF(OR(AS11="",CB11=""),"",AS11/CB11*100) | AU11: =IF(AT11="","",IFERROR(MATCH(AT11,INDEX(Boundaries!$B$2:$I$30,MATCH(CP11,Boundaries!$A$2:$A$30,0),0),1)-1,"")) | AV11: =IF(OR(AU11="",$E11=""),"",AU11-$E11) | AX11: =IF(OR(AW11="",CC11=""),"",AW11/CC11*100) | AY11: =IF(AX11="","",IFERROR(MATCH(AX11,INDEX(Boundaries!$B$2:$I$30,MATCH(CQ11,Boundaries!$A$2:$A$30,0),0),1)-1,"")) | AZ11: =IF(OR(AY11="",$E11=""),"",AY11-$E11) | BB11: =IF(OR(BA11="",CD11=""),"",BA11/CD11*100) | BC11: =IF(BB11="","",IFERROR(MATCH(BB11,INDEX(Boundaries!$B$2:$I$30,MATCH(CR11,Boundaries!$A$2:$A$30,0),0),1)-1,"")) | BD11: =IF(OR(BC11="",$E11=""),"",BC11-$E11) | BF11: =IF(OR(BE11="",CE11=""),"",BE11/CE11*100) | BG11: =IF(BF11="","",IFERROR(MATCH(BF11,INDEX(Boundaries!$B$2:$I$30,MATCH(CS11,Boundaries!$A$2:$A$30,0),0),1)-1,"")) | BH11: =IF(OR(BG11="",$E11=""),"",BG11-$E11) | BJ11: =IF(OR(BI11="",CF11=""),"",BI11/CF11*100) | BK11: =IF(BJ11="","",IFERROR(MATCH(BJ11,INDEX(Boundaries!$B$2:$I$30,MATCH(CT11,Boundaries!$A$2:$A$30,0),0),1)-1,"")) | BL11: =IF(OR(BK11="",$E11=""),"",BK11-$E11) | BN11: =IF(OR(BM11="",CG11=""),"",BM11/CG11*100) | BO11: =IF(BN11="","",IFERROR(MATCH(BN11,INDEX(Boundaries!$B$2:$I$30,MATCH(CU11,Boundaries!$A$2:$A$30,0),0),1)-1,"")) | BP11: =IF(OR(BO11="",$E11=""),"",BO11-$E11) | BR11: =IF(OR(BQ11="",CH11=""),"",BQ11/CH11*100) | BS11: =IF(BR11="","",IFERROR(MATCH(BR11,INDEX(Boundaries!$B$2:$I$30,MATCH(CV11,Boundaries!$A$2:$A$30,0),0),1)-1,"")) | BT11: =IF(OR(BS11="",$E11=""),"",BS11-$E11) | BU11: =IFERROR(INDEX(Assessments!$H$2:$H$600,MATCH($H11&"|"&$I11&"|"&$J11&"|"&1,Assessments!$A$2:$A$600,0)),"") -> 20 | BV11: =IFERROR(INDEX(Assessments!$H$2:$H$600,MATCH($H11&"|"&$I11&"|"&$J11&"|"&2,Assessments!$A$2:$A$600,0)),"") -> 20 | BW11: =IFERROR(INDEX(Assessments!$H$2:$H$600,MATCH($H11&"|"&$I11&"|"&$J11&"|"&3,Assessments!$A$2:$A$600,0)),"") -> 20 | BX11: =IFERROR(INDEX(Assessments!$H$2:$H$600,MATCH($H11&"|"&$I11&"|"&$J11&"|"&4,Assessments!$A$2:$A$600,0)),"") -> 20 | BY11: =IFERROR(INDEX(Assessments!$H$2:$H$600,MATCH($H11&"|"&$I11&"|"&$J11&"|"&5,Assessments!$A$2:$A$600,0)),"") -> 20 | BZ11: =IFERROR(INDEX(Assessments!$H$2:$H$600,MATCH($H11&"|"&$I11&"|"&$J11&"|"&6,Assessments!$A$2:$A$600,0)),"") -> 40 | CA11: =IFERROR(INDEX(Assessments!$H$2:$H$600,MATCH($H11&"|"&$I11&"|"&$J11&"|"&7,Assessments!$A$2:$A$600,0)),"") -> 50 | CB11: =IFERROR(INDEX(Assessments!$H$2:$H$600,MATCH($H11&"|"&$I11&"|"&$J11&"|"&8,Assessments!$A$2:$A$600,0)),"") -> 25 | CC11: =IFERROR(INDEX(Assessments!$H$2:$H$600,MATCH($H11&"|"&$I11&"|"&$J11&"|"&9,Assessments!$A$2:$A$600,0)),"") -> 16 | CD11: =IFERROR(INDEX(Assessments!$H$2:$H$600,MATCH($H11&"|"&$I11&"|"&$J11&"|"&10,Assessments!$A$2:$A$600,0)),"") -> 30 | CE11: =IFERROR(INDEX(Assessments!$H$2:$H$600,MATCH($H11&"|"&$I11&"|"&$J11&"|"&11,Assessments!$A$2:$A$600,0)),"") | CF11: =IFERROR(INDEX(Assessments!$H$2:$H$600,MATCH($H11&"|"&$I11&"|"&$J11&"|"&12,Assessments!$A$2:$A$600,0)),"") | CG11: =IFERROR(INDEX(Assessments!$H$2:$H$600,MATCH($H11&"|"&$I11&"|"&$J11&"|"&13,Assessments!$A$2:$A$600,0)),"") | CH11: =IFERROR(INDEX(Assessments!$H$2:$H$600,MATCH($H11&"|"&$I11&"|"&$J11&"|"&14,Assessments!$A$2:$A$600,0)),"") | CI11: =IFERROR(INDEX(Assessments!$I$2:$I$600,MATCH($H11&"|"&$I11&"|"&$J11&"|"&1,Assessments!$A$2:$A$600,0)),"") -> Geog Paper 1 | CJ11: =IFERROR(INDEX(Assessments!$I$2:$I$600,MATCH($H11&"|"&$I11&"|"&$J11&"|"&2,Assessments!$A$2:$A$600,0)),"") -> Geog Paper 1 | CK11: =IFERROR(INDEX(Assessments!$I$2:$I$600,MATCH($H11&"|"&$I11&"|"&$J11&"|"&3,Assessments!$A$2:$A$600,0)),"") -> Geog Paper 2 | CL11: =IFERROR(INDEX(Assessments!$I$2:$I$600,MATCH($H11&"|"&$I11&"|"&$J11&"|"&4,Assessments!$A$2:$A$600,0)),"") -> Geog Paper 1 | CM11: =IFERROR(INDEX(Assessments!$I$2:$I$600,MATCH($H11&"|"&$I11&"|"&$J11&"|"&5,Assessments!$A$2:$A$600,0)),"") -> Geog Paper 1 | CN11: =IFERROR(INDEX(Assessments!$I$2:$I$600,MATCH($H11&"|"&$I11&"|"&$J11&"|"&6,Assessments!$A$2:$A$600,0)),"") -> Geog Paper 1 | CO11: =IFERROR(INDEX(Assessments!$I$2:$I$600,MATCH($H11&"|"&$I11&"|"&$J11&"|"&7,Assessments!$A$2:$A$600,0)),"") -> Geog Paper 2 | CP11: =IFERROR(INDEX(Assessments!$I$2:$I$600,MATCH($H11&"|"&$I11&"|"&$J11&"|"&8,Assessments!$A$2:$A$600,0)),"") -> Geog Paper 2 | CQ11: =IFERROR(INDEX(Assessments!$I$2:$I$600,MATCH($H11&"|"&$I11&"|"&$J11&"|"&9,Assessments!$A$2:$A$600,0)),"") -> Geog Paper 3 | CR11: =IFERROR(INDEX(Assessments!$I$2:$I$600,MATCH($H11&"|"&$I11&"|"&$J11&"|"&10,Assessments!$A$2:$A$600,0)),"") -> Geog Paper 2 | CS11: =IFERROR(INDEX(Assessments!$I$2:$I$600,MATCH($H11&"|"&$I11&"|"&$J11&"|"&11,Assessments!$A$2:$A$600,0)),"") | CT11: =IFERROR(INDEX(Assessments!$I$2:$I$600,MATCH($H11&"|"&$I11&"|"&$J11&"|"&12,Assessments!$A$2:$A$600,0)),"") | CU11: =IFERROR(INDEX(Assessments!$I$2:$I$600,MATCH($H11&"|"&$I11&"|"&$J11&"|"&13,Assessments!$A$2:$A$600,0)),"") | CV11: =IFERROR(INDEX(Assessments!$I$2:$I$600,MATCH($H11&"|"&$I11&"|"&$J11&"|"&14,Assessments!$A$2:$A$600,0)),"") | CW11: =IFERROR(INDEX(Assessments!$J$2:$J$600,MATCH($H11&"|"&$I11&"|"&$J11&"|"&1,Assessments!$A$2:$A$600,0)),0) -> 1 | CX11: =IFERROR(INDEX(Assessments!$J$2:$J$600,MATCH($H11&"|"&$I11&"|"&$J11&"|"&2,Assessments!$A$2:$A$600,0)),0) -> 1 | CY11: =IFERROR(INDEX(Assessments!$J$2:$J$600,MATCH($H11&"|"&$I11&"|"&$J11&"|"&3,Assessments!$A$2:$A$600,0)),0) -> 1 | CZ11: =IFERROR(INDEX(Assessments!$J$2:$J$600,MATCH($H11&"|"&$I11&"|"&$J11&"|"&4,Assessments!$A$2:$A$600,0)),0) -> 1 | DA11: =IFERROR(INDEX(Assessments!$J$2:$J$600,MATCH($H11&"|"&$I11&"|"&$J11&"|"&5,Assessments!$A$2:$A$600,0)),0) -> 1 | DB11: =IFERROR(INDEX(Assessments!$J$2:$J$600,MATCH($H11&"|"&$I11&"|"&$J11&"|"&6,Assessments!$A$2:$A$600,0)),0) -> 2 | DC11: =IFERROR(INDEX(Assessments!$J$2:$J$600,MATCH($H11&"|"&$I11&"|"&$J11&"|"&7,Assessments!$A$2:$A$600,0)),0) -> 2 | DD11: =IFERROR(INDEX(Assessments!$J$2:$J$600,MATCH($H11&"|"&$I11&"|"&$J11&"|"&8,Assessments!$A$2:$A$600,0)),0) -> 1 | DE11: =IFERROR(INDEX(Assessments!$J$2:$J$600,MATCH($H11&"|"&$I11&"|"&$J11&"|"&9,Assessments!$A$2:$A$600,0)),0) -> 1 | DF11: =IFERROR(INDEX(Assessments!$J$2:$J$600,MATCH($H11&"|"&$I11&"|"&$J11&"|"&10,Assessments!$A$2:$A$600,0)),0) -> 1 | DG11: =IFERROR(INDEX(Assessments!$J$2:$J$600,MATCH($H11&"|"&$I11&"|"&$J11&"|"&11,Assessments!$A$2:$A$600,0)),0) -> 0 | DH11: =IFERROR(INDEX(Assessments!$J$2:$J$600,MATCH($H11&"|"&$I11&"|"&$J11&"|"&12,Assessments!$A$2:$A$600,0)),0) -> 0 | DI11: =IFERROR(INDEX(Assessments!$J$2:$J$600,MATCH($H11&"|"&$I11&"|"&$J11&"|"&13,Assessments!$A$2:$A$600,0)),0) -> 0 | DJ11: =IFERROR(INDEX(Assessments!$J$2:$J$600,MATCH($H11&"|"&$I11&"|"&$J11&"|"&14,Assessments!$A$2:$A$600,0)),0) -> 0 | DK11: =S11 -> 6 | DL11: =W11 -> 6 | DM11: =AA11 -> 5 | DN11: =AE11 -> 7 | DO11: =AI11 -> 7 | DP11: =AM11 -> 6 | DQ11: =AQ11 -> 6 | DR11: =AU11 | DS11: =AY11 | DT11: =BC11 | DU11: =BG11 | DV11: =BK11 | DW11: =BO11 | DX11: =BS11 | DY11: =IF(ISNUMBER(S11),1,"") -> 1 | DZ11: =IF(ISNUMBER(W11),2,"") -> 2 | EA11: =IF(ISNUMBER(AA11),3,"") -> 3 | EB11: =IF(ISNUMBER(AE11),4,"") -> 4 | EC11: =IF(ISNUMBER(AI11),5,"") -> 5 | ED11: =IF(ISNUMBER(AM11),6,"") -> 6 | EE11: =IF(ISNUMBER(AQ11),7,"") -> 7 | EF11: =IF(ISNUMBER(AU11),8,"") | EG11: =IF(ISNUMBER(AY11),9,"") | EH11: =IF(ISNUMBER(BC11),10,"") | EI11: =IF(ISNUMBER(BG11),11,"") | EJ11: =IF(ISNUMBER(BK11),12,"") | EK11: =IF(ISNUMBER(BO11),13,"") | EL11: =IF(ISNUMBER(BS11),14,"") | EM11: =IF(ISNUMBER(R11),R11*CW11,0) -> 65 | EN11: =IF(ISNUMBER(V11),V11*CX11,0) -> 65 | EO11: =IF(ISNUMBER(Z11),Z11*CY11,0) -> 65 | EP11: =IF(ISNUMBER(AD11),AD11*CZ11,0) -> 90 | EQ11: =IF(ISNUMBER(AH11),AH11*DA11,0) -> 90 | ER11: =IF(ISNUMBER(AL11),AL11*DB11,0) -> 125 | ES11: =IF(ISNUMBER(AP11),AP11*DC11,0) -> 136 | ET11: =IF(ISNUMBER(AT11),AT11*DD11,0) -> 0 | EU11: =IF(ISNUMBER(AX11),AX11*DE11,0) -> 0 | EV11: =IF(ISNUMBER(BB11),BB11*DF11,0) -> 0 | EW11: =IF(ISNUMBER(BF11),BF11*DG11,0) -> 0 | EX11: =IF(ISNUMBER(BJ11),BJ11*DH11,0) -> 0 | EY11: =IF(ISNUMBER(BN11),BN11*DI11,0) -> 0 | EZ11: =IF(ISNUMBER(BR11),BR11*DJ11,0) -> 0 | FA11: =IF(ISNUMBER(R11),CW11,0) -> 1 | FB11: =IF(ISNUMBER(V11),CX11,0) -> 1 | FC11: =IF(ISNUMBER(Z11),CY11,0) -> 1 | FD11: =IF(ISNUMBER(AD11),CZ11,0) -> 1 | FE11: =IF(ISNUMBER(AH11),DA11,0) -> 1 | FF11: =IF(ISNUMBER(AL11),DB11,0) -> 2 | FG11: =IF(ISNUMBER(AP11),DC11,0) -> 2 | FH11: =IF(ISNUMBER(AT11),DD11,0) -> 0 | FI11: =IF(ISNUMBER(AX11),DE11,0) -> 0 | FJ11: =IF(ISNUMBER(BB11),DF11,0) -> 0 | FK11: =IF(ISNUMBER(BF11),DG11,0) -> 0 | FL11: =IF(ISNUMBER(BJ11),DH11,0) -> 0 | FM11: =IF(ISNUMBER(BN11),DI11,0) -> 0 | FN11: =IF(ISNUMBER(BR11),DJ11,0) -> 0 | FO11: =IFERROR(INDEX(Lists!$G$2:$G$20,MATCH($I11&"|"&$J11,Lists!$F$2:$F$20,0)),"") -> Geog Overall HL
A12: Maxwell | B12: Barta | C12: 12.3 | D12: KEWR | E12: 5.2 | F12: 6 | H12: Grad 2027 | I12: IB Geography | J12: HL | K12: =IF(OR(M12="",$E12=""),"",M12-$E12) -> -0.2 | L12: =IF(SUM(FA12:FN12)=0,"",SUM(EM12:EZ12)/SUM(FA12:FN12)) -> 60.777778 | M12: =IF(OR(L12="",FO12=""),"",IFERROR(MATCH(L12,INDEX(Boundaries!$B$2:$I$30,MATCH(FO12,Boundaries!$A$2:$A$30,0),0),1)-1,"")) -> 5 | N12: =IF(COUNT($DY12:$EL12)<2,"",INDEX($DK12:$DX12,MAX($DY12:$EL12))-INDEX($DK12:$DX12,MIN($DY12:$EL12))) -> 0 | O12: =IF(COUNT($DY12:$EL12)<2,"",INDEX($DK12:$DX12,MAX($DY12:$EL12))-INDEX($DK12:$DX12,LARGE($DY12:$EL12,2))) -> -1 | P12: =IF(K12="","",IF(K12>=0,"On/above target",IF(AND(N12<>"",N12>=0.5),"Improving towards target",IF(AND(O12<>"",O12<=-0.5),"Declining","Stable below target")))) -> Declining | Q12: 12 | R12: =IF(OR(Q12="",BU12=""),"",Q12/BU12*100) -> 60 | S12: =IF(R12="","",IFERROR(MATCH(R12,INDEX(Boundaries!$B$2:$I$30,MATCH(CI12,Boundaries!$A$2:$A$30,0),0),1)-1,"")) -> 5 | T12: =IF(OR(S12="",$E12=""),"",S12-$E12) -> -0.2 | U12: 12 | V12: =IF(OR(U12="",BV12=""),"",U12/BV12*100) -> 60 | W12: =IF(V12="","",IFERROR(MATCH(V12,INDEX(Boundaries!$B$2:$I$30,MATCH(CJ12,Boundaries!$A$2:$A$30,0),0),1)-1,"")) -> 5 | X12: =IF(OR(W12="",$E12=""),"",W12-$E12) -> -0.2 | Y12: 12 | Z12: =IF(OR(Y12="",BW12=""),"",Y12/BW12*100) -> 60 | AA12: =IF(Z12="","",IFERROR(MATCH(Z12,INDEX(Boundaries!$B$2:$I$30,MATCH(CK12,Boundaries!$A$2:$A$30,0),0),1)-1,"")) -> 5 | AB12: =IF(OR(AA12="",$E12=""),"",AA12-$E12) -> -0.2 | AC12: 13 | AD12: =IF(OR(AC12="",BX12=""),"",AC12/BX12*100) -> 65 | AE12: =IF(AD12="","",IFERROR(MATCH(AD12,INDEX(Boundaries!$B$2:$I$30,MATCH(CL12,Boundaries!$A$2:$A$30,0),0),1)-1,"")) -> 6 | AF12: =IF(OR(AE12="",$E12=""),"",AE12-$E12) -> 0.8 | AG12: 13 | AH12: =IF(OR(AG12="",BY12=""),"",AG12/BY12*100) -> 65 | AI12: =IF(AH12="","",IFERROR(MATCH(AH12,INDEX(Boundaries!$B$2:$I$30,MATCH(CM12,Boundaries!$A$2:$A$30,0),0),1)-1,"")) -> 6 | AJ12: =IF(OR(AI12="",$E12=""),"",AI12-$E12) -> 0.8 | AK12: 25 | AL12: =IF(OR(AK12="",BZ12=""),"",AK12/BZ12*100) -> 62.5 | AM12: =IF(AL12="","",IFERROR(MATCH(AL12,INDEX(Boundaries!$B$2:$I$30,MATCH(CN12,Boundaries!$A$2:$A$30,0),0),1)-1,"")) -> 6 | AN12: =IF(OR(AM12="",$E12=""),"",AM12-$E12) -> 0.8 | AO12: 28 | AP12: =IF(OR(AO12="",CA12=""),"",AO12/CA12*100) -> 56 | AQ12: =IF(AP12="","",IFERROR(MATCH(AP12,INDEX(Boundaries!$B$2:$I$30,MATCH(CO12,Boundaries!$A$2:$A$30,0),0),1)-1,"")) -> 5 | AR12: =IF(OR(AQ12="",$E12=""),"",AQ12-$E12) -> -0.2 | AT12: =IF(OR(AS12="",CB12=""),"",AS12/CB12*100) | AU12: =IF(AT12="","",IFERROR(MATCH(AT12,INDEX(Boundaries!$B$2:$I$30,MATCH(CP12,Boundaries!$A$2:$A$30,0),0),1)-1,"")) | AV12: =IF(OR(AU12="",$E12=""),"",AU12-$E12) | AX12: =IF(OR(AW12="",CC12=""),"",AW12/CC12*100) | AY12: =IF(AX12="","",IFERROR(MATCH(AX12,INDEX(Boundaries!$B$2:$I$30,MATCH(CQ12,Boundaries!$A$2:$A$30,0),0),1)-1,"")) | AZ12: =IF(OR(AY12="",$E12=""),"",AY12-$E12) | BB12: =IF(OR(BA12="",CD12=""),"",BA12/CD12*100) | BC12: =IF(BB12="","",IFERROR(MATCH(BB12,INDEX(Boundaries!$B$2:$I$30,MATCH(CR12,Boundaries!$A$2:$A$30,0),0),1)-1,"")) | BD12: =IF(OR(BC12="",$E12=""),"",BC12-$E12) | BF12: =IF(OR(BE12="",CE12=""),"",BE12/CE12*100) | BG12: =IF(BF12="","",IFERROR(MATCH(BF12,INDEX(Boundaries!$B$2:$I$30,MATCH(CS12,Boundaries!$A$2:$A$30,0),0),1)-1,"")) | BH12: =IF(OR(BG12="",$E12=""),"",BG12-$E12) | BJ12: =IF(OR(BI12="",CF12=""),"",BI12/CF12*100) | BK12: =IF(BJ12="","",IFERROR(MATCH(BJ12,INDEX(Boundaries!$B$2:$I$30,MATCH(CT12,Boundaries!$A$2:$A$30,0),0),1)-1,"")) | BL12: =IF(OR(BK12="",$E12=""),"",BK12-$E12) | BN12: =IF(OR(BM12="",CG12=""),"",BM12/CG12*100) | BO12: =IF(BN12="","",IFERROR(MATCH(BN12,INDEX(Boundaries!$B$2:$I$30,MATCH(CU12,Boundaries!$A$2:$A$30,0),0),1)-1,"")) | BP12: =IF(OR(BO12="",$E12=""),"",BO12-$E12) | BR12: =IF(OR(BQ12="",CH12=""),"",BQ12/CH12*100) | BS12: =IF(BR12="","",IFERROR(MATCH(BR12,INDEX(Boundaries!$B$2:$I$30,MATCH(CV12,Boundaries!$A$2:$A$30,0),0),1)-1,"")) | BT12: =IF(OR(BS12="",$E12=""),"",BS12-$E12) | BU12: =IFERROR(INDEX(Assessments!$H$2:$H$600,MATCH($H12&"|"&$I12&"|"&$J12&"|"&1,Assessments!$A$2:$A$600,0)),"") -> 20 | BV12: =IFERROR(INDEX(Assessments!$H$2:$H$600,MATCH($H12&"|"&$I12&"|"&$J12&"|"&2,Assessments!$A$2:$A$600,0)),"") -> 20 | BW12: =IFERROR(INDEX(Assessments!$H$2:$H$600,MATCH($H12&"|"&$I12&"|"&$J12&"|"&3,Assessments!$A$2:$A$600,0)),"") -> 20 | BX12: =IFERROR(INDEX(Assessments!$H$2:$H$600,MATCH($H12&"|"&$I12&"|"&$J12&"|"&4,Assessments!$A$2:$A$600,0)),"") -> 20 | BY12: =IFERROR(INDEX(Assessments!$H$2:$H$600,MATCH($H12&"|"&$I12&"|"&$J12&"|"&5,Assessments!$A$2:$A$600,0)),"") -> 20 | BZ12: =IFERROR(INDEX(Assessments!$H$2:$H$600,MATCH($H12&"|"&$I12&"|"&$J12&"|"&6,Assessments!$A$2:$A$600,0)),"") -> 40 | CA12: =IFERROR(INDEX(Assessments!$H$2:$H$600,MATCH($H12&"|"&$I12&"|"&$J12&"|"&7,Assessments!$A$2:$A$600,0)),"") -> 50 | CB12: =IFERROR(INDEX(Assessments!$H$2:$H$600,MATCH($H12&"|"&$I12&"|"&$J12&"|"&8,Assessments!$A$2:$A$600,0)),"") -> 25 | CC12: =IFERROR(INDEX(Assessments!$H$2:$H$600,MATCH($H12&"|"&$I12&"|"&$J12&"|"&9,Assessments!$A$2:$A$600,0)),"") -> 16 | CD12: =IFERROR(INDEX(Assessments!$H$2:$H$600,MATCH($H12&"|"&$I12&"|"&$J12&"|"&10,Assessments!$A$2:$A$600,0)),"") -> 30 | CE12: =IFERROR(INDEX(Assessments!$H$2:$H$600,MATCH($H12&"|"&$I12&"|"&$J12&"|"&11,Assessments!$A$2:$A$600,0)),"") | CF12: =IFERROR(INDEX(Assessments!$H$2:$H$600,MATCH($H12&"|"&$I12&"|"&$J12&"|"&12,Assessments!$A$2:$A$600,0)),"") | CG12: =IFERROR(INDEX(Assessments!$H$2:$H$600,MATCH($H12&"|"&$I12&"|"&$J12&"|"&13,Assessments!$A$2:$A$600,0)),"") | CH12: =IFERROR(INDEX(Assessments!$H$2:$H$600,MATCH($H12&"|"&$I12&"|"&$J12&"|"&14,Assessments!$A$2:$A$600,0)),"") | CI12: =IFERROR(INDEX(Assessments!$I$2:$I$600,MATCH($H12&"|"&$I12&"|"&$J12&"|"&1,Assessments!$A$2:$A$600,0)),"") -> Geog Paper 1 | CJ12: =IFERROR(INDEX(Assessments!$I$2:$I$600,MATCH($H12&"|"&$I12&"|"&$J12&"|"&2,Assessments!$A$2:$A$600,0)),"") -> Geog Paper 1 | CK12: =IFERROR(INDEX(Assessments!$I$2:$I$600,MATCH($H12&"|"&$I12&"|"&$J12&"|"&3,Assessments!$A$2:$A$600,0)),"") -> Geog Paper 2 | CL12: =IFERROR(INDEX(Assessments!$I$2:$I$600,MATCH($H12&"|"&$I12&"|"&$J12&"|"&4,Assessments!$A$2:$A$600,0)),"") -> Geog Paper 1 | CM12: =IFERROR(INDEX(Assessments!$I$2:$I$600,MATCH($H12&"|"&$I12&"|"&$J12&"|"&5,Assessments!$A$2:$A$600,0)),"") -> Geog Paper 1 | CN12: =IFERROR(INDEX(Assessments!$I$2:$I$600,MATCH($H12&"|"&$I12&"|"&$J12&"|"&6,Assessments!$A$2:$A$600,0)),"") -> Geog Paper 1 | CO12: =IFERROR(INDEX(Assessments!$I$2:$I$600,MATCH($H12&"|"&$I12&"|"&$J12&"|"&7,Assessments!$A$2:$A$600,0)),"") -> Geog Paper 2 | CP12: =IFERROR(INDEX(Assessments!$I$2:$I$600,MATCH($H12&"|"&$I12&"|"&$J12&"|"&8,Assessments!$A$2:$A$600,0)),"") -> Geog Paper 2 | CQ12: =IFERROR(INDEX(Assessments!$I$2:$I$600,MATCH($H12&"|"&$I12&"|"&$J12&"|"&9,Assessments!$A$2:$A$600,0)),"") -> Geog Paper 3 | CR12: =IFERROR(INDEX(Assessments!$I$2:$I$600,MATCH($H12&"|"&$I12&"|"&$J12&"|"&10,Assessments!$A$2:$A$600,0)),"") -> Geog Paper 2 | CS12: =IFERROR(INDEX(Assessments!$I$2:$I$600,MATCH($H12&"|"&$I12&"|"&$J12&"|"&11,Assessments!$A$2:$A$600,0)),"") | CT12: =IFERROR(INDEX(Assessments!$I$2:$I$600,MATCH($H12&"|"&$I12&"|"&$J12&"|"&12,Assessments!$A$2:$A$600,0)),"") | CU12: =IFERROR(INDEX(Assessments!$I$2:$I$600,MATCH($H12&"|"&$I12&"|"&$J12&"|"&13,Assessments!$A$2:$A$600,0)),"") | CV12: =IFERROR(INDEX(Assessments!$I$2:$I$600,MATCH($H12&"|"&$I12&"|"&$J12&"|"&14,Assessments!$A$2:$A$600,0)),"") | CW12: =IFERROR(INDEX(Assessments!$J$2:$J$600,MATCH($H12&"|"&$I12&"|"&$J12&"|"&1,Assessments!$A$2:$A$600,0)),0) -> 1 | CX12: =IFERROR(INDEX(Assessments!$J$2:$J$600,MATCH($H12&"|"&$I12&"|"&$J12&"|"&2,Assessments!$A$2:$A$600,0)),0) -> 1 | CY12: =IFERROR(INDEX(Assessments!$J$2:$J$600,MATCH($H12&"|"&$I12&"|"&$J12&"|"&3,Assessments!$A$2:$A$600,0)),0) -> 1 | CZ12: =IFERROR(INDEX(Assessments!$J$2:$J$600,MATCH($H12&"|"&$I12&"|"&$J12&"|"&4,Assessments!$A$2:$A$600,0)),0) -> 1 | DA12: =IFERROR(INDEX(Assessments!$J$2:$J$600,MATCH($H12&"|"&$I12&"|"&$J12&"|"&5,Assessments!$A$2:$A$600,0)),0) -> 1 | DB12: =IFERROR(INDEX(Assessments!$J$2:$J$600,MATCH($H12&"|"&$I12&"|"&$J12&"|"&6,Assessments!$A$2:$A$600,0)),0) -> 2 | DC12: =IFERROR(INDEX(Assessments!$J$2:$J$600,MATCH($H12&"|"&$I12&"|"&$J12&"|"&7,Assessments!$A$2:$A$600,0)),0) -> 2 | DD12: =IFERROR(INDEX(Assessments!$J$2:$J$600,MATCH($H12&"|"&$I12&"|"&$J12&"|"&8,Assessments!$A$2:$A$600,0)),0) -> 1 | DE12: =IFERROR(INDEX(Assessments!$J$2:$J$600,MATCH($H12&"|"&$I12&"|"&$J12&"|"&9,Assessments!$A$2:$A$600,0)),0) -> 1 | DF12: =IFERROR(INDEX(Assessments!$J$2:$J$600,MATCH($H12&"|"&$I12&"|"&$J12&"|"&10,Assessments!$A$2:$A$600,0)),0) -> 1 | DG12: =IFERROR(INDEX(Assessments!$J$2:$J$600,MATCH($H12&"|"&$I12&"|"&$J12&"|"&11,Assessments!$A$2:$A$600,0)),0) -> 0 | DH12: =IFERROR(INDEX(Assessments!$J$2:$J$600,MATCH($H12&"|"&$I12&"|"&$J12&"|"&12,Assessments!$A$2:$A$600,0)),0) -> 0 | DI12: =IFERROR(INDEX(Assessments!$J$2:$J$600,MATCH($H12&"|"&$I12&"|"&$J12&"|"&13,Assessments!$A$2:$A$600,0)),0) -> 0 | DJ12: =IFERROR(INDEX(Assessments!$J$2:$J$600,MATCH($H12&"|"&$I12&"|"&$J12&"|"&14,Assessments!$A$2:$A$600,0)),0) -> 0 | DK12: =S12 -> 5 | DL12: =W12 -> 5 | DM12: =AA12 -> 5 | DN12: =AE12 -> 6 | DO12: =AI12 -> 6 | DP12: =AM12 -> 6 | DQ12: =AQ12 -> 5 | DR12: =AU12 | DS12: =AY12 | DT12: =BC12 | DU12: =BG12 | DV12: =BK12 | DW12: =BO12 | DX12: =BS12 | DY12: =IF(ISNUMBER(S12),1,"") -> 1 | DZ12: =IF(ISNUMBER(W12),2,"") -> 2 | EA12: =IF(ISNUMBER(AA12),3,"") -> 3 | EB12: =IF(ISNUMBER(AE12),4,"") -> 4 | EC12: =IF(ISNUMBER(AI12),5,"") -> 5 | ED12: =IF(ISNUMBER(AM12),6,"") -> 6 | EE12: =IF(ISNUMBER(AQ12),7,"") -> 7 | EF12: =IF(ISNUMBER(AU12),8,"") | EG12: =IF(ISNUMBER(AY12),9,"") | EH12: =IF(ISNUMBER(BC12),10,"") | EI12: =IF(ISNUMBER(BG12),11,"") | EJ12: =IF(ISNUMBER(BK12),12,"") | EK12: =IF(ISNUMBER(BO12),13,"") | EL12: =IF(ISNUMBER(BS12),14,"") | EM12: =IF(ISNUMBER(R12),R12*CW12,0) -> 60 | EN12: =IF(ISNUMBER(V12),V12*CX12,0) -> 60 | EO12: =IF(ISNUMBER(Z12),Z12*CY12,0) -> 60 | EP12: =IF(ISNUMBER(AD12),AD12*CZ12,0) -> 65 | EQ12: =IF(ISNUMBER(AH12),AH12*DA12,0) -> 65 | ER12: =IF(ISNUMBER(AL12),AL12*DB12,0) -> 125 | ES12: =IF(ISNUMBER(AP12),AP12*DC12,0) -> 112 | ET12: =IF(ISNUMBER(AT12),AT12*DD12,0) -> 0 | EU12: =IF(ISNUMBER(AX12),AX12*DE12,0) -> 0 | EV12: =IF(ISNUMBER(BB12),BB12*DF12,0) -> 0 | EW12: =IF(ISNUMBER(BF12),BF12*DG12,0) -> 0 | EX12: =IF(ISNUMBER(BJ12),BJ12*DH12,0) -> 0 | EY12: =IF(ISNUMBER(BN12),BN12*DI12,0) -> 0 | EZ12: =IF(ISNUMBER(BR12),BR12*DJ12,0) -> 0 | FA12: =IF(ISNUMBER(R12),CW12,0) -> 1 | FB12: =IF(ISNUMBER(V12),CX12,0) -> 1 | FC12: =IF(ISNUMBER(Z12),CY12,0) -> 1 | FD12: =IF(ISNUMBER(AD12),CZ12,0) -> 1 | FE12: =IF(ISNUMBER(AH12),DA12,0) -> 1 | FF12: =IF(ISNUMBER(AL12),DB12,0) -> 2 | FG12: =IF(ISNUMBER(AP12),DC12,0) -> 2 | FH12: =IF(ISNUMBER(AT12),DD12,0) -> 0 | FI12: =IF(ISNUMBER(AX12),DE12,0) -> 0 | FJ12: =IF(ISNUMBER(BB12),DF12,0) -> 0 | FK12: =IF(ISNUMBER(BF12),DG12,0) -> 0 | FL12: =IF(ISNUMBER(BJ12),DH12,0) -> 0 | FM12: =IF(ISNUMBER(BN12),DI12,0) -> 0 | FN12: =IF(ISNUMBER(BR12),DJ12,0) -> 0 | FO12: =IFERROR(INDEX(Lists!$G$2:$G$20,MATCH($I12&"|"&$J12,Lists!$F$2:$F$20,0)),"") -> Geog Overall HL
A13: Anyssa | B13: Bunnag | C13: 12.3 | D13: KEWR | E13: 6.5 | F13: 7 | H13: Grad 2027 | I13: IB Geography | J13: HL | K13: =IF(OR(M13="",$E13=""),"",M13-$E13) -> -0.5 | L13: =IF(SUM(FA13:FN13)=0,"",SUM(EM13:EZ13)/SUM(FA13:FN13)) -> 68.777778 | M13: =IF(OR(L13="",FO13=""),"",IFERROR(MATCH(L13,INDEX(Boundaries!$B$2:$I$30,MATCH(FO13,Boundaries!$A$2:$A$30,0),0),1)-1,"")) -> 6 | N13: =IF(COUNT($DY13:$EL13)<2,"",INDEX($DK13:$DX13,MAX($DY13:$EL13))-INDEX($DK13:$DX13,MIN($DY13:$EL13))) -> -2 | O13: =IF(COUNT($DY13:$EL13)<2,"",INDEX($DK13:$DX13,MAX($DY13:$EL13))-INDEX($DK13:$DX13,LARGE($DY13:$EL13,2))) -> 0 | P13: =IF(K13="","",IF(K13>=0,"On/above target",IF(AND(N13<>"",N13>=0.5),"Improving towards target",IF(AND(O13<>"",O13<=-0.5),"Declining","Stable below target")))) -> Stable below target | Q13: 15 | R13: =IF(OR(Q13="",BU13=""),"",Q13/BU13*100) -> 75 | S13: =IF(R13="","",IFERROR(MATCH(R13,INDEX(Boundaries!$B$2:$I$30,MATCH(CI13,Boundaries!$A$2:$A$30,0),0),1)-1,"")) -> 7 | T13: =IF(OR(S13="",$E13=""),"",S13-$E13) -> 0.5 | U13: 13 | V13: =IF(OR(U13="",BV13=""),"",U13/BV13*100) -> 65 | W13: =IF(V13="","",IFERROR(MATCH(V13,INDEX(Boundaries!$B$2:$I$30,MATCH(CJ13,Boundaries!$A$2:$A$30,0),0),1)-1,"")) -> 6 | X13: =IF(OR(W13="",$E13=""),"",W13-$E13) -> -0.5 | Y13: 17 | Z13: =IF(OR(Y13="",BW13=""),"",Y13/BW13*100) -> 85 | AA13: =IF(Z13="","",IFERROR(MATCH(Z13,INDEX(Boundaries!$B$2:$I$30,MATCH(CK13,Boundaries!$A$2:$A$30,0),0),1)-1,"")) -> 7 | AB13: =IF(OR(AA13="",$E13=""),"",AA13-$E13) -> 0.5 | AC13: 15 | AD13: =IF(OR(AC13="",BX13=""),"",AC13/BX13*100) -> 75 | AE13: =IF(AD13="","",IFERROR(MATCH(AD13,INDEX(Boundaries!$B$2:$I$30,MATCH(CL13,Boundaries!$A$2:$A$30,0),0),1)-1,"")) -> 7 | AF13: =IF(OR(AE13="",$E13=""),"",AE13-$E13) -> 0.5 | AG13: 15 | AH13: =IF(OR(AG13="",BY13=""),"",AG13/BY13*100) -> 75 | AI13: =IF(AH13="","",IFERROR(MATCH(AH13,INDEX(Boundaries!$B$2:$I$30,MATCH(CM13,Boundaries!$A$2:$A$30,0),0),1)-1,"")) -> 7 | AJ13: =IF(OR(AI13="",$E13=""),"",AI13-$E13) -> 0.5 | AK13: 24 | AL13: =IF(OR(AK13="",BZ13=""),"",AK13/BZ13*100) -> 60 | AM13: =IF(AL13="","",IFERROR(MATCH(AL13,INDEX(Boundaries!$B$2:$I$30,MATCH(CN13,Boundaries!$A$2:$A$30,0),0),1)-1,"")) -> 5 | AN13: =IF(OR(AM13="",$E13=""),"",AM13-$E13) -> -1.5 | AO13: 31 | AP13: =IF(OR(AO13="",CA13=""),"",AO13/CA13*100) -> 62 | AQ13: =IF(AP13="","",IFERROR(MATCH(AP13,INDEX(Boundaries!$B$2:$I$30,MATCH(CO13,Boundaries!$A$2:$A$30,0),0),1)-1,"")) -> 5 | AR13: =IF(OR(AQ13="",$E13=""),"",AQ13-$E13) -> -1.5 | AT13: =IF(OR(AS13="",CB13=""),"",AS13/CB13*100) | AU13: =IF(AT13="","",IFERROR(MATCH(AT13,INDEX(Boundaries!$B$2:$I$30,MATCH(CP13,Boundaries!$A$2:$A$30,0),0),1)-1,"")) | AV13: =IF(OR(AU13="",$E13=""),"",AU13-$E13) | AX13: =IF(OR(AW13="",CC13=""),"",AW13/CC13*100) | AY13: =IF(AX13="","",IFERROR(MATCH(AX13,INDEX(Boundaries!$B$2:$I$30,MATCH(CQ13,Boundaries!$A$2:$A$30,0),0),1)-1,"")) | AZ13: =IF(OR(AY13="",$E13=""),"",AY13-$E13) | BB13: =IF(OR(BA13="",CD13=""),"",BA13/CD13*100) | BC13: =IF(BB13="","",IFERROR(MATCH(BB13,INDEX(Boundaries!$B$2:$I$30,MATCH(CR13,Boundaries!$A$2:$A$30,0),0),1)-1,"")) | BD13: =IF(OR(BC13="",$E13=""),"",BC13-$E13) | BF13: =IF(OR(BE13="",CE13=""),"",BE13/CE13*100) | BG13: =IF(BF13="","",IFERROR(MATCH(BF13,INDEX(Boundaries!$B$2:$I$30,MATCH(CS13,Boundaries!$A$2:$A$30,0),0),1)-1,"")) | BH13: =IF(OR(BG13="",$E13=""),"",BG13-$E13) | BJ13: =IF(OR(BI13="",CF13=""),"",BI13/CF13*100) | BK13: =IF(BJ13="","",IFERROR(MATCH(BJ13,INDEX(Boundaries!$B$2:$I$30,MATCH(CT13,Boundaries!$A$2:$A$30,0),0),1)-1,"")) | BL13: =IF(OR(BK13="",$E13=""),"",BK13-$E13) | BN13: =IF(OR(BM13="",CG13=""),"",BM13/CG13*100) | BO13: =IF(BN13="","",IFERROR(MATCH(BN13,INDEX(Boundaries!$B$2:$I$30,MATCH(CU13,Boundaries!$A$2:$A$30,0),0),1)-1,"")) | BP13: =IF(OR(BO13="",$E13=""),"",BO13-$E13) | BR13: =IF(OR(BQ13="",CH13=""),"",BQ13/CH13*100) | BS13: =IF(BR13="","",IFERROR(MATCH(BR13,INDEX(Boundaries!$B$2:$I$30,MATCH(CV13,Boundaries!$A$2:$A$30,0),0),1)-1,"")) | BT13: =IF(OR(BS13="",$E13=""),"",BS13-$E13) | BU13: =IFERROR(INDEX(Assessments!$H$2:$H$600,MATCH($H13&"|"&$I13&"|"&$J13&"|"&1,Assessments!$A$2:$A$600,0)),"") -> 20 | BV13: =IFERROR(INDEX(Assessments!$H$2:$H$600,MATCH($H13&"|"&$I13&"|"&$J13&"|"&2,Assessments!$A$2:$A$600,0)),"") -> 20 | BW13: =IFERROR(INDEX(Assessments!$H$2:$H$600,MATCH($H13&"|"&$I13&"|"&$J13&"|"&3,Assessments!$A$2:$A$600,0)),"") -> 20 | BX13: =IFERROR(INDEX(Assessments!$H$2:$H$600,MATCH($H13&"|"&$I13&"|"&$J13&"|"&4,Assessments!$A$2:$A$600,0)),"") -> 20 | BY13: =IFERROR(INDEX(Assessments!$H$2:$H$600,MATCH($H13&"|"&$I13&"|"&$J13&"|"&5,Assessments!$A$2:$A$600,0)),"") -> 20 | BZ13: =IFERROR(INDEX(Assessments!$H$2:$H$600,MATCH($H13&"|"&$I13&"|"&$J13&"|"&6,Assessments!$A$2:$A$600,0)),"") -> 40 | CA13: =IFERROR(INDEX(Assessments!$H$2:$H$600,MATCH($H13&"|"&$I13&"|"&$J13&"|"&7,Assessments!$A$2:$A$600,0)),"") -> 50 | CB13: =IFERROR(INDEX(Assessments!$H$2:$H$600,MATCH($H13&"|"&$I13&"|"&$J13&"|"&8,Assessments!$A$2:$A$600,0)),"") -> 25 | CC13: =IFERROR(INDEX(Assessments!$H$2:$H$600,MATCH($H13&"|"&$I13&"|"&$J13&"|"&9,Assessments!$A$2:$A$600,0)),"") -> 16 | CD13: =IFERROR(INDEX(Assessments!$H$2:$H$600,MATCH($H13&"|"&$I13&"|"&$J13&"|"&10,Assessments!$A$2:$A$600,0)),"") -> 30 | CE13: =IFERROR(INDEX(Assessments!$H$2:$H$600,MATCH($H13&"|"&$I13&"|"&$J13&"|"&11,Assessments!$A$2:$A$600,0)),"") | CF13: =IFERROR(INDEX(Assessments!$H$2:$H$600,MATCH($H13&"|"&$I13&"|"&$J13&"|"&12,Assessments!$A$2:$A$600,0)),"") | CG13: =IFERROR(INDEX(Assessments!$H$2:$H$600,MATCH($H13&"|"&$I13&"|"&$J13&"|"&13,Assessments!$A$2:$A$600,0)),"") | CH13: =IFERROR(INDEX(Assessments!$H$2:$H$600,MATCH($H13&"|"&$I13&"|"&$J13&"|"&14,Assessments!$A$2:$A$600,0)),"") | CI13: =IFERROR(INDEX(Assessments!$I$2:$I$600,MATCH($H13&"|"&$I13&"|"&$J13&"|"&1,Assessments!$A$2:$A$600,0)),"") -> Geog Paper 1 | CJ13: =IFERROR(INDEX(Assessments!$I$2:$I$600,MATCH($H13&"|"&$I13&"|"&$J13&"|"&2,Assessments!$A$2:$A$600,0)),"") -> Geog Paper 1 | CK13: =IFERROR(INDEX(Assessments!$I$2:$I$600,MATCH($H13&"|"&$I13&"|"&$J13&"|"&3,Assessments!$A$2:$A$600,0)),"") -> Geog Paper 2 | CL13: =IFERROR(INDEX(Assessments!$I$2:$I$600,MATCH($H13&"|"&$I13&"|"&$J13&"|"&4,Assessments!$A$2:$A$600,0)),"") -> Geog Paper 1 | CM13: =IFERROR(INDEX(Assessments!$I$2:$I$600,MATCH($H13&"|"&$I13&"|"&$J13&"|"&5,Assessments!$A$2:$A$600,0)),"") -> Geog Paper 1 | CN13: =IFERROR(INDEX(Assessments!$I$2:$I$600,MATCH($H13&"|"&$I13&"|"&$J13&"|"&6,Assessments!$A$2:$A$600,0)),"") -> Geog Paper 1 | CO13: =IFERROR(INDEX(Assessments!$I$2:$I$600,MATCH($H13&"|"&$I13&"|"&$J13&"|"&7,Assessments!$A$2:$A$600,0)),"") -> Geog Paper 2 | CP13: =IFERROR(INDEX(Assessments!$I$2:$I$600,MATCH($H13&"|"&$I13&"|"&$J13&"|"&8,Assessments!$A$2:$A$600,0)),"") -> Geog Paper 2 | CQ13: =IFERROR(INDEX(Assessments!$I$2:$I$600,MATCH($H13&"|"&$I13&"|"&$J13&"|"&9,Assessments!$A$2:$A$600,0)),"") -> Geog Paper 3 | CR13: =IFERROR(INDEX(Assessments!$I$2:$I$600,MATCH($H13&"|"&$I13&"|"&$J13&"|"&10,Assessments!$A$2:$A$600,0)),"") -> Geog Paper 2 | CS13: =IFERROR(INDEX(Assessments!$I$2:$I$600,MATCH($H13&"|"&$I13&"|"&$J13&"|"&11,Assessments!$A$2:$A$600,0)),"") | CT13: =IFERROR(INDEX(Assessments!$I$2:$I$600,MATCH($H13&"|"&$I13&"|"&$J13&"|"&12,Assessments!$A$2:$A$600,0)),"") | CU13: =IFERROR(INDEX(Assessments!$I$2:$I$600,MATCH($H13&"|"&$I13&"|"&$J13&"|"&13,Assessments!$A$2:$A$600,0)),"") | CV13: =IFERROR(INDEX(Assessments!$I$2:$I$600,MATCH($H13&"|"&$I13&"|"&$J13&"|"&14,Assessments!$A$2:$A$600,0)),"") | CW13: =IFERROR(INDEX(Assessments!$J$2:$J$600,MATCH($H13&"|"&$I13&"|"&$J13&"|"&1,Assessments!$A$2:$A$600,0)),0) -> 1 | CX13: =IFERROR(INDEX(Assessments!$J$2:$J$600,MATCH($H13&"|"&$I13&"|"&$J13&"|"&2,Assessments!$A$2:$A$600,0)),0) -> 1 | CY13: =IFERROR(INDEX(Assessments!$J$2:$J$600,MATCH($H13&"|"&$I13&"|"&$J13&"|"&3,Assessments!$A$2:$A$600,0)),0) -> 1 | CZ13: =IFERROR(INDEX(Assessments!$J$2:$J$600,MATCH($H13&"|"&$I13&"|"&$J13&"|"&4,Assessments!$A$2:$A$600,0)),0) -> 1 | DA13: =IFERROR(INDEX(Assessments!$J$2:$J$600,MATCH($H13&"|"&$I13&"|"&$J13&"|"&5,Assessments!$A$2:$A$600,0)),0) -> 1 | DB13: =IFERROR(INDEX(Assessments!$J$2:$J$600,MATCH($H13&"|"&$I13&"|"&$J13&"|"&6,Assessments!$A$2:$A$600,0)),0) -> 2 | DC13: =IFERROR(INDEX(Assessments!$J$2:$J$600,MATCH($H13&"|"&$I13&"|"&$J13&"|"&7,Assessments!$A$2:$A$600,0)),0) -> 2 | DD13: =IFERROR(INDEX(Assessments!$J$2:$J$600,MATCH($H13&"|"&$I13&"|"&$J13&"|"&8,Assessments!$A$2:$A$600,0)),0) -> 1 | DE13: =IFERROR(INDEX(Assessments!$J$2:$J$600,MATCH($H13&"|"&$I13&"|"&$J13&"|"&9,Assessments!$A$2:$A$600,0)),0) -> 1 | DF13: =IFERROR(INDEX(Assessments!$J$2:$J$600,MATCH($H13&"|"&$I13&"|"&$J13&"|"&10,Assessments!$A$2:$A$600,0)),0) -> 1 | DG13: =IFERROR(INDEX(Assessments!$J$2:$J$600,MATCH($H13&"|"&$I13&"|"&$J13&"|"&11,Assessments!$A$2:$A$600,0)),0) -> 0 | DH13: =IFERROR(INDEX(Assessments!$J$2:$J$600,MATCH($H13&"|"&$I13&"|"&$J13&"|"&12,Assessments!$A$2:$A$600,0)),0) -> 0 | DI13: =IFERROR(INDEX(Assessments!$J$2:$J$600,MATCH($H13&"|"&$I13&"|"&$J13&"|"&13,Assessments!$A$2:$A$600,0)),0) -> 0 | DJ13: =IFERROR(INDEX(Assessments!$J$2:$J$600,MATCH($H13&"|"&$I13&"|"&$J13&"|"&14,Assessments!$A$2:$A$600,0)),0) -> 0 | DK13: =S13 -> 7 | DL13: =W13 -> 6 | DM13: =AA13 -> 7 | DN13: =AE13 -> 7 | DO13: =AI13 -> 7 | DP13: =AM13 -> 5 | DQ13: =AQ13 -> 5 | DR13: =AU13 | DS13: =AY13 | DT13: =BC13 | DU13: =BG13 | DV13: =BK13 | DW13: =BO13 | DX13: =BS13 | DY13: =IF(ISNUMBER(S13),1,"") -> 1 | DZ13: =IF(ISNUMBER(W13),2,"") -> 2 | EA13: =IF(ISNUMBER(AA13),3,"") -> 3 | EB13: =IF(ISNUMBER(AE13),4,"") -> 4 | EC13: =IF(ISNUMBER(AI13),5,"") -> 5 | ED13: =IF(ISNUMBER(AM13),6,"") -> 6 | EE13: =IF(ISNUMBER(AQ13),7,"") -> 7 | EF13: =IF(ISNUMBER(AU13),8,"") | EG13: =IF(ISNUMBER(AY13),9,"") | EH13: =IF(ISNUMBER(BC13),10,"") | EI13: =IF(ISNUMBER(BG13),11,"") | EJ13: =IF(ISNUMBER(BK13),12,"") | EK13: =IF(ISNUMBER(BO13),13,"") | EL13: =IF(ISNUMBER(BS13),14,"") | EM13: =IF(ISNUMBER(R13),R13*CW13,0) -> 75 | EN13: =IF(ISNUMBER(V13),V13*CX13,0) -> 65 | EO13: =IF(ISNUMBER(Z13),Z13*CY13,0) -> 85 | EP13: =IF(ISNUMBER(AD13),AD13*CZ13,0) -> 75 | EQ13: =IF(ISNUMBER(AH13),AH13*DA13,0) -> 75 | ER13: =IF(ISNUMBER(AL13),AL13*DB13,0) -> 120 | ES13: =IF(ISNUMBER(AP13),AP13*DC13,0) -> 124 | ET13: =IF(ISNUMBER(AT13),AT13*DD13,0) -> 0 | EU13: =IF(ISNUMBER(AX13),AX13*DE13,0) -> 0 | EV13: =IF(ISNUMBER(BB13),BB13*DF13,0) -> 0 | EW13: =IF(ISNUMBER(BF13),BF13*DG13,0) -> 0 | EX13: =IF(ISNUMBER(BJ13),BJ13*DH13,0) -> 0 | EY13: =IF(ISNUMBER(BN13),BN13*DI13,0) -> 0 | EZ13: =IF(ISNUMBER(BR13),BR13*DJ13,0) -> 0 | FA13: =IF(ISNUMBER(R13),CW13,0) -> 1 | FB13: =IF(ISNUMBER(V13),CX13,0) -> 1 | FC13: =IF(ISNUMBER(Z13),CY13,0) -> 1 | FD13: =IF(ISNUMBER(AD13),CZ13,0) -> 1 | FE13: =IF(ISNUMBER(AH13),DA13,0) -> 1 | FF13: =IF(ISNUMBER(AL13),DB13,0) -> 2 | FG13: =IF(ISNUMBER(AP13),DC13,0) -> 2 | FH13: =IF(ISNUMBER(AT13),DD13,0) -> 0 | FI13: =IF(ISNUMBER(AX13),DE13,0) -> 0 | FJ13: =IF(ISNUMBER(BB13),DF13,0) -> 0 | FK13: =IF(ISNUMBER(BF13),DG13,0) -> 0 | FL13: =IF(ISNUMBER(BJ13),DH13,0) -> 0 | FM13: =IF(ISNUMBER(BN13),DI13,0) -> 0 | FN13: =IF(ISNUMBER(BR13),DJ13,0) -> 0 | FO13: =IFERROR(INDEX(Lists!$G$2:$G$20,MATCH($I13&"|"&$J13,Lists!$F$2:$F$20,0)),"") -> Geog Overall HL
